Workbook

Sheet Flow
A1: Flow

Sheet Case HFG
A2: PT. BAJA SEMESTA MANDIRI
B4: Tgl | C4: Qty | D4: Harga | E4: Total | F4: PPN | G4: Sub Total
A5: PO AWAL | B5: 46252 | C5: 3805.9993 | D5: 16936.94 | E5: =C5*D5 -> 64461982 | F5: =E5*11% -> 7090818 | G5: =SUM(E5:F5) -> 71552800
A7: DP | B7: 46253 | G7: 71552800 | H7: Pengakuan PPN DP
A9: RECEIPT ITEM | B9: 46253 | C9: 3805.9993 | D9: 16936.94 | E9: =C9*D9 -> 64461982
A11: PRODUKSI | B11: 46256 | C11: 681 | D11: FG | E11: =C11*18800 -> 12802800 | G11: =E11*20% -> 2560560 | H11: DIKOMPENSASI 20% | I11: =G11/1.11 -> 2306810.8 | J11: --> nilai tanpa ppn
A13: RETUR | B13: 46260 | C13: =C5-C11 -> 3124.9993 | G13: =C13*18800 -> 58749987 | H13: INC PPN
A15: TUKAR COIL | B15: 46260 | C15: 3870 | D15: 16936.94 | E15: =C15*D15 -> 65545958 | F15: =E15*11% -> 7210055.4 | G15: =SUM(E15:F15) -> 72756013 | H15: SELISIH TIMBANGAN
A17: PELUNASAN | B17: 46266 | C17: 3870 | D17: 16936.94 | E17: =C17*D17 -> 65545958
C18: 681 | D18: 16936.94 | E18: =C18*D18 -> 11534056
D19: Sub Total | E19: =SUM(E17:E18) -> 77080014
D20: Pot | E20: =I11 -> 2306810.8
D21: DP | E21: =E5 -> 64461982
D22: KB | E22: =E19-E20-E21 -> 10311221 | F22: BELUM PPN
E23: =E22*11% -> 1134234.3
E24: =SUM(E22:E23) -> 11445455

Sheet Simulasi Claim Kombinasi jalur
A1: Simulasi awal dari PO sampai akhirnya terbit Debit Note Kombinasi 2 jalur (Kompensasi dan Retur) Untuk dipakai ke Pembayaran
A3: 1. PO
B4: Supplier : | C4: PT. BAJA SEMESTA MANDIRI
B6: No | C6: Item | D6: Qty | E6: Price Unit | F6: Total Price
B7: 1 | C7: Coil A | D7: ='Case HFG'!C5 -> 3805.9993 | E7: ='Case HFG'!D5 -> 16936.94 | F7: =D7*E7 -> 64461982
E9: DPP : | F9: =F7*(11/12) -> 59090150
E10: PPn : | F10: =F9*12% -> 7090818
E11: Total Price + PPn : | F11: =F10+F7 -> 71552800
A13: 2. Receive Invoice DP
B15: DP : | C15: 1
B16: Nilai DP : | C16: =C15*F7 -> 64461982
B18: DPP : | C18: =C16*(11/12) -> 59090150
B19: PPn : | C19: =C18*12% -> 7090818
B20: Total Invoice : | C20: =C19+C16 -> 71552800
B22: Jurnal :
C23: COA | D23: Debit | E23: Kredit
C24: DP | D24: =C16 -> 64461982
C25: PPn | D25: =C19 -> 7090818
C26: Hutang | E26: =C20 -> 71552800
D27: =SUM(D24:D26) -> 71552800 | E27: =SUM(E24:E26) -> 71552800
A28: 3. Pembayaran DP
B30: Total Invoice : | C30: =C20 -> 71552800
B32: Total Bayar : | C32: =C30 -> 71552800
B33: Admin : | C33: 0
B35: Jurnal :
C36: COA | D36: Debit | E36: Kredit
C37: Hutang | D37: =E26 -> 71552800
C38: Bank | E38: =C32 -> 71552800
C39: Bank Admin | E39: =C33 -> 0
C40: Admin | D40: =C33 -> 0
D41: =SUM(D37:D40) -> 71552800 | E41: =SUM(E37:E40) -> 71552800
A43: 4. Incoming Material Gudang
B45: Total Incoming : | C45: ='Case HFG'!C9 -> 3805.9993
B46: Nilai/Unit : | C46: ='Case HFG'!D9 -> 16936.94
B47: Nilai Incoming : | C47: =C45*C46 -> 64461982
B49: Jurnal :
C50: COA | D50: Debit | E50: Kredit
C51: Inventory | D51: =C47 -> 64461982
C52: Unbill | E52: =D51-D24 -> 0
C53: DP | E53: =C47 -> 64461982
...

Sheet Tampungan Hold
A1: Tambahan tampilan
A3: 1 | B3: Tampilan stok, disamakan dengan tampilan dari menu Warehouse > Gudang Coil > Stock. Ditambahkan juga tampungan untuk material dengan status "HOLD" di tab "Material On Hold"

Sheet Saat Claim dari Produksi
A1: Laporan Produksi (Modifikasi dari Model Program saat ini (Submenu : Production Report)
K2: Catatan
B3: SPK : | C3: (Select SPK) | K3: Konsistensi Nama di semua table
K4: Siapkan table database, misalnya - Tabel WIP, - Tabel finish good, - Tabel produk bermasalah (hold) - Tabel Reject Supplier
B5: Tgl Produksi | C5: Mesin | D5: Helper Name | E5: Setter Name | F5: Start Time | G5: Finished Time
B6: (Select Tgl) | C6: (Select Mesin) | D6: (Select Helper) | E6: (Select Setter) | F6: (Input HH:MM) | G6: (Input HH:MM) | K6: Buat beberapa simulasi - Simulasi buka packing tidak di proses - Simulasi buka packing proses kw 2 100 m - Simulasi produksi full - Simulasi produksi masih ada sisa coil
B8: Data Packing List
B9: Coil Used | C9: Gross Weight packing list | D9: Nett Weight Packing list | E9: Total Meter
B10: Select coil dari gudang Produksi 2 | C10: Database | D10: Database | E10: Database
B11: Select coil dari gudang WIP Sisa Coil | C11: Database | D11: Database | E11: Database
A13: 1 | B13: Packing (Actual Condition --> Setelah Unpack)
C14: Gross Weight Actual | F14: Nett Weight Actual
B15: Tgl Unpack | C15: Gross Weight Actual | D15: Kulit | E15: Clamp / Ring (kg) | F15: Net Weight Aktual | G15: Wrapping (kg) | H15: % Selisih | I15: Coil Condition
B16: (Select Tgl) | C16: (Input Kg) | D16: (Input Kg) | E16: (Input Kg) | F16: (Input Kg) | G16: (Input Kg) | H16: %selisih net actual vs packing list | I16: (Input Free Text)
A18: 2 | B18: Finish Good KW 1
B19: Produk 1 : | C19: (Sesuai Product yang di SPK) | D19: Input Detail Production
B20: Produk 2 : | C20: (Sesuai Product yang di SPK) | D20: Input Detail Production
B21: Produk 3 : | C21: (Sesuai Product yang di SPK) | D21: Input Detail Production
B23: Add Stok Bebas
B24: Stok Bebas 1 : | C24: (Select Master Product) | D24: Input Detail Production
C26: Pilihan 1 (Total+Qty) | D26: Pilihan 2 (Per Pcs+Qty)
B28: Pilihan 1 : | C28: Qty | D28: Berat Total (Kg) | E28: Berat/Pcs (Kg)
C29: (Input Qty) | D29: (Input Kg) | E29: (Total Berat/Qty) | F29: --> Pakai pilihan 1
B31: Pilihan 2 : | C31: Qty | D31: Berat Total (Kg) | E31: Berat/Pcs (Kg)
C32: (Input Qty) | D32: (Qty x Berat/pcs) | E32: (Input Kg)
A35: 3 | B35: KW 2
B36: Internal
B37: Add KW 2
B38: No | C38: Size (m) | D38: Qty KW 2 | E38: Berat Total (kg) | F38: Berat/Pcs (Kg) | G38: Nama KW 2 | H38: Keterangan
B39: 1 | C39: (input qty) | D39: (input qty) | E39: (input qty) | F39: Berat total / Qty Kw2 | G39: (Input free text)
B40: 2
B42: Supplier
B43: Add KW 2
B44: No | C44: Size (m) | D44: Qty KW 2 | E44: Berat Total (kg) | F44: Berat/Pcs (Kg) | G44: Nama KW 2 | H44: Keterangan | I44: -> Contoh : KW 2 akibat white rust
B45: 1
B46: 2
A48: 4 | B48: Sisa Coil
B49: Berat : | C49: (input qty)
A52: 5 | B52: Total Berat Hold Coil
B53: Berat : | C53: (input qty) | D53: --> Tidak dijurnal, karena akan diclaim. Setelah itu, lanjut produksi atau simpan di Gudang
...

Sheet Konsep&Sim Modul Claim
A1: Konsep & Simulasi Material Claim (Pemilihan Keputusan)
A3: Konsep
M5: Fitur :
A6: Header : | M6: 1 | N6: Email, untuk kirim email keluhan ke Supplier
C7: Supplier : | D7: (Filter by Supplier) | H7: Email | I7: Process Decision | M7: 2 | N7: Penerimaan Credit Note, Untuk input nilai claim ke supplier
M8: 3 | N8: Process Act, memilih tindakan selanjutnya
B10: No | C10: Nama Supplier | D10: Nama Material | E10: No. Coil Packing List | F10: No. PO Pembelian | G10: Berat Coil (Kg) | H10: Problem | I10: Status Claim | J10: Action
B11: 1 | C11: PT Baja Semesta Mandiri | D11: Galvalum 025 | E11: BSM-C001 | F11: PO-001 | G11: ='Case HFG'!C11 -> 681 | H11: KW 2 | I11: "Kompensasi" | K11: View Alasan Hold dari Produksi | M11: Detail untuk email :
B12: 2 | C12: PT Baja Semesta Mandiri | D12: Galvalum 025 | E12: BSM-C002 | F12: PO-001 | G12: ='Case HFG'!C13 -> 3124.9993 | H12: Karat | I12: "Retur" | K12: View Alasan Hold dari Produksi
S14: Butuh master setting email?
A18: Detail Process Decision :
B20: No | C20: Nama Supplier | D20: Nama Material | E20: No. Coil Packing List | F20: No. PO Pembelian | G20: Berat Coil (Kg) | H20: Problem
C23: Decision
C24: Kompensasi : | D24: 1. Debit Note | F24: (Input Nilai Debit Note) | G24: --> Otomatis masuk ke List Debit Note
D25: 2. Lanjut Produksi | F25: (Input Catatan Untuk Produksi) | G25: --> Statusnya otomatis berubah dari "Hold" menjadi bisa dipakai
D26: 3. Jual Material | F26: (Input Keterangan) | G26: --> Otomatis masuk ke Inventory Material Khusus dijual (Gudang Slitting)
C28: Retur :
D29: 1. Retur ke Supplier | F29: (Input Keterangan) | G29: --> Otomatis masuk ke List SPK Repack dan SJ Retur
C31: Cancel | D31: Confirm
A34: Simulasi Claim Jalur Kompensasi
A37: Header :
C38: Supplier : | D38: (Filter by Supplier) | H38: Email | I38: Process Decision
B41: No | C41: Nama Supplier | D41: Nama Material | E41: No. Coil Packing List | F41: No. PO Pembelian | G41: Berat Coil (Kg) | H41: Problem | I41: Status Claim | J41: Action
B42: 1 | C42: PT Baja Semesta Mandiri | D42: Galvalum 025 | E42: BSM-C001 | F42: PO-001 | G42: =$G$11 -> 681 | H42: KW 2 | I42: "Kompensasi" | K42: View Alasan Hold dari Produksi
B43: 2 | C43: PT Baja Semesta Mandiri | D43: Galvalum 025 | E43: BSM-C002 | F43: PO-001 | G43: =$G$12 -> 3124.9993 | H43: Karat | I43: "Retur" | K43: View Alasan Hold dari Produksi
A46: Detail Process Act :
B48: No | C48: Nama Supplier | D48: Nama Material | E48: No. Coil Packing List | F48: No. PO Pembelian | G48: Berat Coil (Kg) | H48: Problem
B49: 1 | C49: PT Baja Semesta Mandiri | D49: Galvalum 025 | E49: BSM-C001 | F49: PO-001 | G49: 681 | H49: KW 2
C51: Decision
C52: Kompensasi : | D52: 1. Debit Note | F52: ='Simulasi Claim Kombinasi jalur'!D77 -> 2306810.8
D53: 2. Lanjut Produksi
D54: 3. Jual Material
C56: Retur :
D57: 1. Retur ke Supplier
C59: Cancel | D59: Confirm
A61: Simulasi Claim Jalur Retur
A64: Header :
C65: Supplier : | D65: (Filter by Supplier) | H65: Email | I65: Process Decision
B68: No | C68: Nama Supplier | D68: Nama Material | E68: No. Coil Packing List | F68: No. PO Pembelian | G68: Berat Coil (Kg) | H68: Problem | I68: Status Claim | J68: Action
B69: 1 | C69: PT Baja Semesta Mandiri | D69: Galvalum 025 | E69: BSM-C001 | F69: PO-001 | G69: =$G$11 -> 681 | H69: KW 2 | I69: "Kompensasi" | K69: View Alasan Hold dari Produksi
...

Sheet Konsep&Sim Debit Note
A1: Konsep Terbit Debit Note
A3: 1. Konsep dan Simulasi Debit Note dari Retur
A4: 1. Header :
A6: No. Debit Note | B6: Tgl Terbit | C6: Nama Supplier | D6: Mata Uang | E6: Total Nilai Klaim | F6: Jalur | G6: Status Dokumen | H6: Action
A7: DN-2609-001 | B7: 46276 | C7: PT Zibo Internasional | D7: USD | E7: 14277.4 | F7: Kompensasi | G7: Sudah Terbit | H7: View | I7: Print | J7: Edit | K7: Create
A8: DN-2609-002 | B8: 46276 | C8: YINGLI INTERNATIONAL | D8: USD | E8: 2637.4 | F8: Kompensasi | G8: Belum Terima Uang | H8: View | I8: Print | J8: Edit | K8: Create
A9: DN-2609-003 | B9: 46277 | C9: PT Baja Lokal Sejahtera | D9: IDR | E9: 25500000 | F9: Kompensasi | G9: Sudah Terima Uang | H9: View | I9: Print | J9: Edit | K9: Create
A10: DN-2609-004 | B10: 46277 | C10: PT XYZ | D10: IDR | E10: 20000000 | F10: Retur | G10: Sudah Alokasi ke Hutang | H10: View | I10: Print | J10: Edit | K10: Create
A11: DN-2609-005 | B11: 46277 | C11: ='Konsep&Sim Modul Claim'!C49 -> PT Baja Semesta Mandiri | D11: IDR | E11: ='Konsep&Sim Modul Claim'!F52 -> 2306810.8 | F11: Kompensasi | G11: Belum Terbit | H11: View | I11: Print | J11: Edit | K11: Create
A12: DN-2609-006 | B12: 46277 | C12: ='Konsep&Sim Modul Claim'!C76 -> PT Baja Semesta Mandiri | D12: IDR | E12: ='Simulasi Claim Kombinasi jalur'!F81 -> 52927928 | F12: Retur | G12: Belum Terbit | H12: View | I12: Print | J12: Edit | K12: Create
A14: 2. Detail Saat Create Debit Note
B16: Jenis Debit Note
B17: Retur | D17: --> Jika Retur, Otomatis tarik Detil Surat Jalan
A19: No | B19: Nama Supplier | C19: Nama Material | D19: No. Coil Packing List | E19: No. PO Pembelian | F19: Berat Coil (Kg) | G19: Problem | H19: Surat Jalan
A20: 1 | B20: ='Konsep&Sim Modul Claim'!C76 -> PT Baja Semesta Mandiri | C20: ='Konsep&Sim Modul Claim'!D76 -> Galvalum 025 | D20: ='Konsep&Sim Modul Claim'!E76 -> BSM-C002 | E20: ='Konsep&Sim Modul Claim'!F76 -> PO-001 | F20: ='Konsep&Sim Modul Claim'!G76 -> 3124.9993 | G20: ='Konsep&Sim Modul Claim'!H76 -> Karat | H20: ='Konsep&Sim SJ Retur'!B34 -> SJ-03
B22: Total Debit Note : | C22: =E12 -> 52927928 | D22: (Tarik nilai dari modul claim)
B23: Kurs : | C23: 1 | D23: (Input Kurs untuk Mata Uang Non IDR)
B24: Total Debit Note (IDR) : | C24: =C22*C23 -> 52927928 | D24: (Nanti akan masuk ke menu Penerimaan Uang dari Supplier)
D27: Cancel | E27: Create Debt Note
A29: 2. Konsep dan Simulasi Debit Note dari Kompensasi
A30: 1. Header :
A32: No. Debit Note | B32: Tgl Terbit | C32: Nama Supplier | D32: Mata Uang | E32: Total Nilai Klaim | F32: Jalur | G32: Status Dokumen | H32: Action
A33: DN-2609-001 | B33: 46276 | C33: PT Zibo Internasional | D33: USD | E33: 14277.4 | F33: Kompensasi | G33: Sudah Terbit | H33: View | I33: Print | J33: Edit | K33: Create
A34: DN-2609-002 | B34: 46276 | C34: YINGLI INTERNATIONAL | D34: USD | E34: 2637.4 | F34: Kompensasi | G34: Belum Terima Uang | H34: View | I34: Print | J34: Edit | K34: Create
A35: DN-2609-003 | B35: 46277 | C35: PT Baja Lokal Sejahtera | D35: IDR | E35: 25500000 | F35: Kompensasi | G35: Sudah Terima Uang | H35: View | I35: Print | J35: Edit | K35: Create
A36: DN-2609-004 | B36: 46277 | C36: PT XYZ | D36: IDR | E36: 20000000 | F36: Retur | G36: Sudah Alokasi ke Hutang | H36: View | I36: Print | J36: Edit | K36: Create
A37: DN-2609-005 | B37: 46277 | C37: =C11 -> PT Baja Semesta Mandiri | D37: =D11 -> IDR | E37: =E11 -> 2306810.8 | F37: =F11 -> Kompensasi | G37: Belum Terbit | H37: View | I37: Print | J37: Edit | K37: Create
A38: DN-2609-006 | B38: 46277 | C38: =C12 -> PT Baja Semesta Mandiri | D38: =D12 -> IDR | E38: =E12 -> 52927928 | F38: =F12 -> Retur | G38: Belum Terbit | H38: View | I38: Print | J38: Edit | K38: Create
A40: 2. Detail Saat Create Debit Note
B42: Jenis Debit Note
C43: Kompensasi
A45: No | B45: Nama Supplier | C45: Nama Material | D45: No. Coil Packing List | E45: No. PO Pembelian | F45: Berat Coil (Kg) | G45: Problem | H45: Surat Jalan
A46: 1 | B46: ='Konsep&Sim Modul Claim'!C49 -> PT Baja Semesta Mandiri | C46: ='Konsep&Sim Modul Claim'!D49 -> Galvalum 025 | D46: ='Konsep&Sim Modul Claim'!E49 -> BSM-C001 | E46: ='Konsep&Sim Modul Claim'!F49 -> PO-001 | F46: ='Konsep&Sim Modul Claim'!G49 -> 681 | G46: ='Konsep&Sim Modul Claim'!H49 -> KW 2
B48: Total Debit Note : | C48: =E37 -> 2306810.8 | D48: (Tarik nilai dari modul claim)
B49: Kurs : | C49: 1 | D49: (Input Kurs untuk Mata Uang Non IDR)
B50: Total Debit Note (IDR) : | C50: =C48*C49 -> 2306810.8 | D50: (Nanti akan masuk ke menu Penerimaan Uang dari Supplier)
D53: Cancel | E53: Create Debt Note
B55: Jurnal :
B56: COA | C56: Debit | D56: Credit
B57: Debit Note Kompensasi | C57: =C50 -> 2306810.8
...

Sheet Konsep&Sim SJ Retur
A1: Konsep & Simulasi Surat Jalan Retur
A3: 1. SPK Re-Pack untuk diretur ke Supplier (Modul SPK Re-Pack) | J3: Ket :
J4: 1. Create SPK, untuk membuat SPK Re-Pack ke Produksi sebelum dikirim
A5: Header : | J5: 2. Confirm SPK, untuk konfirmasi bahwa Material sudah Re-Pack
J6: 3. View, untuk melihat hasil input
A7: No. SPK Repack | B7: Tgl Terbit | C7: Supplier | D7: Material Claim | E7: Status SPK | F7: Action | J7: 4. Print, Untuk print out SPK
A8: SPK-RP-260901 | B8: 46276 | C8: PT Harapan Fajar Gemilang | D8: 1. Galvalum 025 2. Galvalum 020 | E8: COMPLETED | F8: View | G8: Print
A9: SPK-RP-260902 | B9: 46277 | C9: YINGLI INTERNATIONAL | D9: 1. Galvalum 025 2. Galvalum 014 | E9: ON PROGRESS | F9: Confirm SPK | G9: View | H9: Print
A10: - | B10: - | C10: ='Konsep&Sim Modul Claim'!C70 -> PT Baja Semesta Mandiri | D10: ='Konsep&Sim Modul Claim'!D70 -> Galvalum 025 | E10: WAITING | F10: Create SPK
A12: Detail :
A13: Informasi Surat Jalan
A14: No. SPK Repack : | B14: SPK-RP-260905 | C14: (Auto Generate)
A15: Tgl Perintah Kerja : | B15: 46278 | C15: (Select Tgl SPK)
A17: No | B17: Nama Supplier | C17: Nama Material | D17: No. Coil Packing List | E17: No. PO Pembelian | F17: Berat Coil (Kg) | G17: Problem
A18: 1 | B18: =C10 -> PT Baja Semesta Mandiri | C18: =D10 -> Galvalum 025 | D18: ='Konsep&Sim Modul Claim'!E70 -> BSM-C002 | E18: PO-001 | F18: ='Konsep&Sim Modul Claim'!G76 -> 3124.9993 | G18: ='Konsep&Sim Modul Claim'!H76 -> Karat
B20: Cancel | C20: Create SPK
A23: 2. Surat Jalan Retur (Berdasarkan SPK Re-Pack Retur) --> Modul Surat Jalan Retur
A25: Header :
A27: No. Surat Jalan | B27: Tgl Terbit | C27: Supplier | D27: Material Claim | E27: Status Surat Jalan | F27: Action
A28: SJ-01 | B28: 46276 | C28: PT Harapan Fajar Gemilang | D28: 1. Galvalum 025 2. Galvalum 020 | E28: SJ CONFIRMED | F28: View | G28: Print | J28: Ket :
A29: SJ-02 | B29: 46277 | C29: YINGLI INTERNATIONAL | D29: 1. Galvalum 025 2. Galvalum 014 | E29: NOT CONFIRMED | F29: Confirm SJ | G29: View | H29: Print | J29: 1. Create SJ, untuk membuat Surat Jalan dari SPK Re-Pack yang sudah selesai
A30: - | B30: - | C30: =B18 -> PT Baja Semesta Mandiri | D30: =C18 -> Galvalum 025 | E30: WAITING SJ | F30: Create SJ | J30: 2. Confirm SJ, untuk konfirmasi bahwa Surat Jalan diterima Supplier
J31: 3. View, untuk melihat hasil input
A32: Detail : | J32: 4. Print, Untuk print out Surat Jalan
A33: Informasi Surat Jalan
A34: No. Surat Jalan : | B34: SJ-03 | C34: (Auto Generate)
A35: Tgl Perintah Kerja : | B35: 46278 | C35: (Select Tgl SPK)
A36: Alamat : | B36: =C30 -> PT Baja Semesta Mandiri
A37: Driver : | B37: Bpk Andi (Contoh)
A38: No.Polisi Truk : | B38: B 1234 HFG
A41: No | B41: Nama Supplier | C41: Nama Material | D41: No. Coil Packing List | E41: No. PO Pembelian | F41: Berat Coil (Kg) | G41: Problem
A42: 1 | B42: =B18 -> PT Baja Semesta Mandiri | C42: =C18 -> Galvalum 025 | D42: =D18 -> BSM-C002 | E42: =E18 -> PO-001 | F42: =F18 -> 3124.9993 | G42: =G18 -> Karat
B44: Cancel | C44: Create SJ
B47: Jurnal :
B48: COA | C48: Debit | D48: Credit
B49: In Transit | C49: ='Simulasi Claim Kombinasi jalur'!F81 -> 52927928
B50: Inventory | D50: ='Simulasi Claim Kombinasi jalur'!F81 -> 52927928
A52: 3. Konfirmasi Surat Jalan Retur (sudah diterima supplier)
A54: Header :
A56: No. Surat Jalan | B56: Tgl Terbit | C56: Supplier | D56: Material Claim | E56: Status Surat Jalan | F56: Action
...

Sheet Konsep&Sim Bayar PO with DN
A1: Konsep & Simulasi Pembayaran PO menggunakan Debit Note
A3: 1. Konsep Pembayaran PO menggunakan Debit Note
B18: Alokasi Debit Note : | C18: (Add Debit Note) | F18: Nilai Debit Note : | G18: (Muncul sesuai Nilai Debit Note dipilih
A34: 2. SImulasi Pembayaran PO menggunakan Debit Note
B49: Alokasi Debit Note : | C49: ='Konsep&Sim Debit Note'!A11 -> DN-2609-005 | F49: Nilai Debit Note : | G49: ='Konsep&Sim Debit Note'!E11 -> 2306810.8
C50: ='Konsep&Sim Debit Note'!A12 -> DN-2609-006 | G50: ='Konsep&Sim Debit Note'!E12 -> 52927928

Sheet Konsep&Sim Tagihan DN Langsung
B2: Penagihan Debit Note ke Supplier
B3: Debit note yang ditagihkan langsung ke supplier (bukan sebagai pengurang PO)
B5: DAFTAR DEBIT NOTE SIAP DITAGIH
B7: No. Debit Note | C7: Supplier | D7: Jalur Asal | E7: Nominal | F7: Status | G7: Action
B8: DN-0231 | C8: PT Baja Lokal Sejahtera | D8: Kompensasi | E8: 45200000 | F8: Belum ditagih | G8: [ Buat penagihan ]
B9: DN-0227 | C9: PT XYZ | D9: Kompensasi | E9: 29000000 | F9: Belum ditagih | G9: [ Buat penagihan ]
B10: DN-0225 | C10: PT Saranabaja | D10: Retur | E10: 30000000 | F10: Sudah ditagih | G10: -
B13: DETAIL: BUAT PENAGIHAN - DN-0231 (PT Saranabaja)
B15: Jalur asal | D15: Kompensasi
B16: Tanggal debit note terbit | D16: 08 Sep 2026
B17: Nominal debit note | D17: =E10 -> 30000000
B19: Info: Debit note ini tidak dialokasikan ke PO manapun. Tagihan dikirim langsung ke supplier dan otomatis muncul di menu Penerimaan Uang dari Supplier setelah diterbitkan.
B21: Tanggal jatuh tempo tagihan | C21: 25/09/2026
B22: Catatan tagihan (opsional)
B25: [ Batal ] | C25: [ Terbitkan Tagihan ]
B28: Catatan: setelah diterbitkan, baris ini otomatis muncul di sheet 01 - List Penerimaan (Jalur Kompensasi/Retur sesuai asal).

Sheet Header - List Penerimaan
B2: Penerimaan Uang dari Supplier | H2: [ Export ]
B3: Daftar debit note yang menunggu atau sudah diterima pembayarannya
B5: Total belum diterima | D5: Jalur retur | E5: Jalur kompensasi | G5: Diterima bulan ini
B6: Rp 184.500.000 | D6: Rp 92.000.000 | E6: Rp 92.500.000 | G6: Rp 67.200.000
B8: [ Cari no. debit note / supplier... ] | D8: Semua jalur ▾ | E8: Semua status ▾ | G8: Tanggal: dd/mm/yyyy ▾
B10: No. Debit Note | C10: Tanggal Terbit | D10: Supplier | E10: Jalur | F10: Nominal | G10: Status | H10: Aksi
B11: DN-KOMP-0231 | C11: 08 Sep 2026 | D11: PT Zibo Internasional | E11: Kompensasi | F11: 45200000 | G11: Belum diterima | H11: [ Konfirmasi terima ]
B12: DN-RETUR-0118 | C12: 07 Sep 2026 | D12: PT Baja Lokal Sejahtera | E12: Retur | F12: 32000000 | G12: Belum diterima | H12: [ Konfirmasi terima ]
B13: DN-KOMP-0230 | C13: 05 Sep 2026 | D13: YINGLI INTERNATIONAL | E13: Kompensasi | F13: 18300000 | G13: Sudah diterima | H13: -
B14: DN-RETUR-0117 | C14: 03 Sep 2026 | D14: PT Krakatau Steel | E14: Retur | F14: 60000000 | G14: Belum diterima | H14: [ Konfirmasi terima ]
B15: DN-KOMP-0229 | C15: 01 Sep 2026 | D15: PT Saranabaja | E15: Retur | F15: 30000000 | G15: Sudah diterima | H15: -
B18: Catatan: baris pada tabel muncul otomatis saat task 'Terbitkan Debit Note Jalur Retur' / 'Jalur Kompensasi' selesai di proses sebelumnya. Sheet ini adalah wireframe mentah (bukan tampilan final) untuk simulasi alur.

Sheet Detail-Penerimaan Retur
B2: Konfirmasi Penerimaan Uang
B3: DN-RETUR-0118 | D3: Jalur Retur
B5: REFERENSI PROSES
B6: No. claim material | D6: CLM-0092
B7: Supplier | D7: PT Saranabaja
B8: No. surat jalan | D8: SJ-2026-0455
B9: Material | D9: Coil SPHC 1.2mm, 2 koil
B10: Tanggal debit note terbit | D10: 07 Sep 2026
B12: Nominal debit note | D12: 30000000
B14: DETAIL PENERIMAAN (diisi user)
B15: Tanggal diterima | C15: 11/09/2026
B16: Rekening penerima | C16: BCA - 001 302 5567 (Rek. Operasional)
B17: Nominal diterima | C17: 30000000
B18: Bukti transfer | C18: [ Unggah file ]
B19: Catatan (opsional)
B21: PREVIEW JURNAL OTOMATIS
B22: (Db) Bank | D22: =C17 -> 30000000
B23: (Cr) Debit Note | D23: =C17 -> 30000000
B24: * Jika jalur = Kompensasi, jurnal otomatis berubah menjadi (Db) Bank / (Cr) Pendapatan
B26: [ Batal ] | C26: [ Konfirmasi & Posting Jurnal ]
B29: Catatan: wireframe mentah untuk simulasi internal, bukan tampilan final UI/UX.

Sheet Detail-Penerimaan Kompensasi
B2: Konfirmasi Penerimaan Uang
B3: DN-KOMP-0231 | D3: Jalur Kompensasi
B5: REFERENSI PROSES
B6: No. claim material | D6: CLM-0101
B7: Supplier | D7: PT Zibo Internasional
B8: No. list debit note (kompensasi) | D8: LDK-2026-0057
B9: Material | D9: Reject material - Coil HRC 2.0mm
B10: Tanggal debit note terbit | D10: 08 Sep 2026
B12: Nominal debit note | D12: 45200000
B14: DETAIL PENERIMAAN (diisi user)
B15: Tanggal diterima | C15: 11/09/2026
B16: Rekening penerima | C16: BCA - 001 302 5567 (Rek. Operasional)
B17: Nominal diterima | C17: Rp 45.200.000
B18: Bukti transfer | C18: [ Unggah file ]
B19: Catatan (opsional)
B21: PREVIEW JURNAL OTOMATIS
B22: (Db) Bank | D22: 45200000
B23: (Cr) Debit Note | D23: 45200000
B24: * Jika jalur = Retur, jurnal otomatis berubah menjadi (Db) Bank / (Cr) Hutang
B26: [ Batal ] | C26: [ Konfirmasi & Posting Jurnal ]
B29: Catatan: wireframe mentah untuk simulasi internal, bukan tampilan final UI/UX.
