Workbook

Sheet Ide
A1: Ide Improvement
A3: Berat produk spandek dihitung dari ketebalan coil (BMT – Base Metal Thickness) menggunakan rumus dasar density baja, ditambah faktor koreksi karena profil gelombang (corrugation) menambah luas material dibanding lebar efektif terpasang.
A8: Rumus Dasar
B9: Berat (kg/m²) = Ketebalan (mm) × Density Baja (7,85) × Faktor Profil
A10: Density baja = 7,85 gram/cm³ (standar untuk baja lapis/galvalume)
A11: Faktor profil = koreksi karena gelombang spandek butuh material lebih panjang dari lebar efektifnya — biasanya 1,00–1,05 tergantung tinggi gelombang/jenis profil (spandek reguler vs. spandek tebal/heavy profile beda faktornya)
A16: Tabel Referensi Umum (per m², faktor profil ≈ 1,0 - estimasi standar pasar)
B17: Ketebalan/BMT (mm) | C17: Berat per m² (kg)
B18: 0.2 | C18: 1.57
B19: 0.25 | C19: 1.96
B20: 0.3 | C20: 2.36
B21: 0.35 | C21: 2.75
B22: 0.4 | C22: 3.14
B23: 0.45 | C23: 3.53
B24: 0.5 | C24: 3.93
B25: 0.6 | C25: 4.71
B26: 0.7 | C26: 5.5
A28: Alur Konversi Kg → Meter | G28: Note :Kenapa harus lewat "berat per meter lari" dulu, bukan langsung konversi harga? Karena yang dijual per meter itu 1 meter panjang, dengan lebar tetap sesuai profil (bukan 1 meter persegi). Jadi konversinya murni fisik (berat material yang terpakai untuk 1 meter panjang), baru dikalikan harga per kg.
A30: Langkah 1: Berat per m² (kg/m²) → dari tabel ketebalan yang sudah kita bahas
A31: Langkah 2: Berat per Meter Lari (kg/m) = Berat per m² × Lebar Efektif (m)
A32: Langkah 3: Biaya Material per Meter (Rp/m) = Berat per Meter Lari (kg/m) × Harga Coil (Rp/kg)
A34: Contoh Lanjutan dari Perhitungan Sebelumnya
B35: Parameter | C35: Nilai | D35: Validasi | E35: Satuan
B36: BMT (Base Material Thickness) | C36: 0.30 mm | D36: 0.3 | E36: mm
B37: Berat per m² | C37: 2.36 kg/m² | D37: =D36*7.85*1 -> 2.355 | E37: kg/m2
B38: Lebar Efektif | C38: 1.015 m | D38: 1.015 | E38: m
B39: Berat per Meter Lari | C39: 2.36 × 1.015 = 2.395 kg/m | D39: =D37*D38 -> 2.390325 | E39: kg/m
B40: Harga Coil | C40: Rp16,936.94/kg | D40: 16936.94 | E40: Rp/Kg
B41: Biaya Material per Meter | C41: 2.395 × 16,936.94 ≈ Rp40,564/meter | D41: =D39*D40 -> 40484.791 | E41: Rp/m | F41: --> selisih karena desimal

Sheet Simulasi ide (copy)per kg
A1: 1. Master Product
B3: Level 1 : | C3: Atap
B4: Level 2 : | C4: Spandek
B5: Level 3 : | C5: Mini Polos
B6: Level 4 : | C6: SPANDEK POLOS MINI ECO 0.25 X 750
B8: Panjang : | C8: 6 | D8: Meter
B9: Tebal : | C9: 0.25 | D9: mm | E9: --> Tebal tidak perlu di master produk, nanti cukup di BOM nya saja ada varian tebal
B10: Lebar : | C10: 750 | D10: mm | E10: --> Lebar tetap dari Master Product, karena setiap lebar bisa memilki ketebalan yang berbeda
B11: Berat/unit : | C11: 6 | D11: Kg | E11: --> Tidak perlu ada ukuran per unit. Diganti menjadi Berat per Meter
A13: 2. BOM Material
B15: Produk : | C15: SPANDEK POLOS MINI ECO 0.25 X 750 X 6 M
B17: Material yang bisa dipakai:
B18: 1 | C18: GALVALUM MOTHER BORON 0.14-1219-AZ70-G550-
B19: 2 | C19: GALVALUM MOTHER BORON 0.15-1219-AZ70-G550-
B20: Note : | C20: BOM sudah menggunakaan tebal material saat ini yaitu 0,14mm --> sebelumnya bisa pakai tebal 0.15 atau >0.15
B22: Kesimpulan : | C22: 1 Produk bisa menggunakan beberapa varian material
A24: 3. Berat Masing-masing material
B25: Contoh cara baca :
G43: Berat : | H43: 0.23 | I43: mm
G44: Lebar : | H44: 1219 | I44: mm | J44: Lebar slit : | K44: 135 | L44: Contoh kasus roll slit
G45: Jumlah Slit : | H45: =H44/K44 -> 9.0296296 | I45: roll
G46: Berat/meter 1 roll : | H46: 0.24 | I46: Kg
G47: Total berat mother coil : | H47: =H46*H45 -> 2.1671111
G49: Standard berat/meter mother coil : | H49: =1000/470 -> 2.1276596
G50: Selisih : | H50: =ABS(H49-H47) -> 0.039451537 | I50: toleransi : +-5Kg --> masih masuk toleransi
B53: Aktual Material Spandek :
I57: usd/kg | J57: Kurs | K57: Rp/Kg
I58: =737/1000 -> 0.737 | J58: 18000 | K58: =I58*J58 -> 13266
I59: =725/1000 -> 0.725 | J59: 18000 | K59: =I59*J59 -> 13050
I60: =698/1000 -> 0.698 | J60: 18000 | K60: =I60*J60 -> 12564
B63: Detil Info dari Kontrak Supplier Material | F63: Cek saja
B64: Tebal | C64: Lebar | D64: Berat/meter | E64: Berat/Roll Mother coil | F64: Aktual berat/meter | G64: Selisih
B65: 0.14 | C65: 1219 | D65: 1.34 | E65: 755 | F65: =1000/E65 -> 1.3245033 | G65: =ABS(D65-F65) -> 0.015496689 | I65: Data yang dibutuhkan untuk Konversi Costing Kg ke Pricelist Meter
B66: 0.15 | C66: 1219 | D66: 1.44 | E66: 706 | F66: =1000/E66 -> 1.4164306 | G66: =ABS(D66-F66) -> 0.023569405
B67: 0.18 | C67: 1219 | D67: 1.72 | E67: 590 | F67: =1000/E67 -> 1.6949153 | G67: =ABS(D67-F67) -> 0.025084746
A70: 4. Proses Costing per Kg
B72: Produk : | C72: SPANDEK POLOS MINI ECO 0.25 X 750 X 6 M
B73: Varian BOM : | C73: =C18 -> GALVALUM MOTHER BORON 0.14-1219-AZ70-G550-
B74: 1 Meter :
B76: No | C76: Element Costing | D76: Reference (Rp/Kg) | E76: Kg/Meter | F76: Rate Cost | G76: Cost | H76: Satuan | I76: Rp/Kg
...

Sheet Simulasi Program
A1: Simulasi Program
A3: 1. Master Produk (List Produk untuk Product Catalog)
B5: Product Type | C5: Product Category | D5: Product Jenis | E5: Product Master | F5: Panjang | G5: Tebal | H5: Lebar
B6: Atap | C6: Spandek | D6: Polos | E6: HARAPAN SPANDEK POLOS ECO 0.25 X 6 M | F6: 6 | G6: 0.25 | H6: 750
A8: 2. Master Material
B10: Metal Type | C10: Slitted/Non Slit | D10: Boron/Non Boron | E10: Material Name | F10: Width | G10: Thickness | H10: Berat/Meter | I10: --> Berat/Meter perlu ditambahkan di Master
B11: Galvalum | C11: Mother | D11: Boron | E11: GALVALUM MOTHER BORON 0.14-1219-AZ70-G550- | F11: 914 | G11: 0.14 | H11: 1.34
B12: Galvalum | C12: Mother | D12: Boron | E12: GALVALUM MOTHER BORON 0.15-1219-AZ70-G550- | F12: 914 | G12: 0.15 | H12: 1.44
A14: 3. Price Reference
B15: History Pembelian : | F15: History Price/Unit (USD) Material
B16: Metal Type | C16: Slitted/Non Slit | D16: Boron/Non Boron | E16: Material Name | F16: Januari | G16: Februari | H16: Maret | I16: April | J16: Mei | K16: Juni | L16: Latest Price | M16: Average Price
B17: Galvalum | C17: Mother | D17: Boron | E17: =E11 -> GALVALUM MOTHER BORON 0.14-1219-AZ70-G550- | F17: 0.8 | H17: 0.81 | K17: 0.737 | L17: =K17 -> 0.737 | M17: =AVERAGE(F17:K17) -> 0.78233333
B18: Galvalum | C18: Mother | D18: Boron | E18: =E12 -> GALVALUM MOTHER BORON 0.15-1219-AZ70-G550- | F18: 0.79 | H18: 0.8 | K18: 0.725 | L18: =K18 -> 0.725 | M18: =AVERAGE(F18:K18) -> 0.77166667
B21: Kurs Update:
B22: No | C22: Currency | D22: Kurs | E22: Last Updated | F22: Updated By
B23: 1 | C23: USD | D23: 17863 | E23: 46301 | F23: accounting
B26: Price Reference :
B27: Metal Type | C27: Slitted/Non Slit | D27: Boron/Non Boron | E27: Material Name | F27: Harga Pembelian Terakhir | G27: Harga Pembelian Rata-rata | H27: Keputusan Pemakaian Price Reference | I27: Final Price Reference (USD) | J27: Final Price Reference (IDR)
B28: Galvalum | C28: Mother | D28: Boron | E28: =E17 -> GALVALUM MOTHER BORON 0.14-1219-AZ70-G550- | F28: =L17 -> 0.737 | G28: =M17 -> 0.78233333 | H28: Harga Terakhir | I28: =IF(H28="Harga Terakhir",F28,G28) -> 0.737 | J28: =I28*$D$23 -> 13165.031 | K28: --> Bisa edit
B29: Galvalum | C29: Mother | D29: Boron | E29: =E18 -> GALVALUM MOTHER BORON 0.15-1219-AZ70-G550- | F29: =L18 -> 0.725 | G29: =M18 -> 0.77166667 | H29: Harga Terakhir | I29: =IF(H29="Harga Terakhir",F29,G29) -> 0.725 | J29: =I29*$D$23 -> 12950.675 | K29: --> Bisa edit
A33: 3. BOM Produk (dibedakan menjadi beberapa varian tebal)
B35: ADD BOM
B36: No | C36: No. Uniq ID | D36: Base Product | E36: Base Material | F36: Varian Thickness | G36: Latest Update | H36: Update by | I36: Action
B37: 1 | C37: Type 001.1 | D37: =E6 -> HARAPAN SPANDEK POLOS ECO 0.25 X 6 M | E37: =E11 -> GALVALUM MOTHER BORON 0.14-1219-AZ70-G550- | F37: =VLOOKUP(E37,$E$11:$G$12,3,0) -> 0.14 | G37: 46301 | H37: Engineering | I37: View | J37: Edit | K37: Delete | L37: --> Punya uniq ID sendiri
B38: 2 | C38: Type 001.2 | D38: =E6 -> HARAPAN SPANDEK POLOS ECO 0.25 X 6 M | E38: =E12 -> GALVALUM MOTHER BORON 0.15-1219-AZ70-G550- | F38: =VLOOKUP(E38,$E$11:$G$12,3,0) -> 0.15 | G38: 46301 | H38: Engineering | I38: View | J38: Edit | K38: Delete | L38: --> Punya uniq ID sendiri, karena beda tebal
A41: 4. Flow Process & Cycletime (Cycletime per Kategori Produk)
B43: No | C43: Product Category | D43: Costcentre/Area | E43: Process Name | F43: Machine | G43: Cycletime (Menit) | H43: Man Power | I43: Man Hour | R43: Spandek :
B44: 1 | C44: Spandek | D44: Spandek Area | E44: Cutting Spandek | F44: Spandek | G44: =T46 -> 0.041666667 | H44: 1 | I44: =(G44*H44)/60 -> 0.00069444444 | R44: 24 | S44: mtr | T44: 60 | U44: detik
R45: 1 | S45: mtr | T45: =R46*T44 -> 2.5 | U45: detik
R46: =R45/R44 -> 0.041666667 | T46: =T45/T44 -> 0.041666667 | U46: menit
T47: =T46/60 -> 0.00069444444
A54: 5. Man Power Rate
A56: Add | B56: # | C56: Salary Direct Man Power | D56: Nilai | E56: Keterangan | F56: Action
B57: 1 | C57: Gaji Pokok | D57: 4828884 | E57: per bulan | F57: Delete
B58: 2 | C58: Tunjangan Keluarga | D58: 15000 | E58: per bulan | F58: Delete
B59: 3 | C59: Tunjangan Jabatan | D59: 100000 | E59: per bulan | F59: Delete
B60: 4 | C60: THR | D60: 402407 | E60: per bulan | F60: Delete
B61: 5 | C61: Cuti | D61: 193155.36 | E61: per bulan | F61: Delete
B62: 6 | C62: Uang Makan | D62: 200000 | E62: per 25 hari | F62: Delete
B63: 7 | C63: Transport | D63: 225000 | E63: per 25 hari | F63: Delete
...

Sheet Simulasi Costing
A2: 1. Simulasi | E2: (Referensi Harga pembelian dari kontrak supplier) | J2: Rupiah/Meter | Z2: Rupiah/Kg | AP2: Pricelist (Catalog)
A3: No | B3: Master Produk | C3: BOM Material (Varian Tebal) | D3: No.Uniq ID | E3: Price Reference (USD/Kg) | F3: Update Kurs | G3: Price Reference (Rp/Kg) | H3: Berat/Meter | I3: Price Reference (Rp/Mtr) | J3: Material Cost | K3: Man Power Cost | L3: Bahan Pendukung Khusus | M3: FOH | N3: Consumables (5% Material Cost) | O3: Scrap (2% Material Cost) | P3: Biaya Koordinasi (Rp200/Kg) | Q3: Other Cost (Sales, Marketing) | R3: Other Cost (Transport) | S3: Other Cost (Finance, admin) | T3: Other Cost (Management Fee) | U3: Other Cost (Interest) | V3: Other Cost (Profit 5% dari HPP) | W3: Bottom Price | X3: Negotiation Allowance (5% dari Bottom Price) | Y3: Price List/Meter | Z3: Material Cost | AA3: Man Power Cost | AB3: Bahan Pendukung Khusus | AC3: FOH | AD3: Consumables (5% Material Cost) | AE3: Scrap (2% Material Cost) | AF3: Biaya Koordinasi (Rp200/Kg) | AG3: Other Cost (Sales, Marketing) | AH3: Other Cost (Transport) | AI3: Other Cost (Finance, admin) | AJ3: Other Cost (Management Fee) | AK3: Other Cost (Interest) | AL3: Other Cost (Profit 5% dari HPP) | AM3: Bottom Price | AN3: Negotiation Allowance (5% dari Bottom Price) | AO3: Price List/Kg | AP3: Ukuran Produk (Meter) | AQ3: Pricelist Produk/Meter | AR3: Pricelist Produk/Kg
A4: 1 | B4: ='Simulasi Program'!D37 -> HARAPAN SPANDEK POLOS ECO 0.25 X 6 M | C4: ='Simulasi Program'!E37 -> GALVALUM MOTHER BORON 0.14-1219-AZ70-G550- | D4: ='Simulasi Program'!C37 -> Type 001.1 | E4: ='Simulasi Program'!I28 -> 0.737 | F4: ='Simulasi Program'!$D$23 -> 17863 | G4: ='Simulasi Program'!$J$28 -> 13165.031 | H4: ='Simulasi Program'!H11 -> 1.34 | I4: =G4*H4 -> 17641.142 | J4: =I4 -> 17641.142 | K4: ='Simulasi Program'!$C$87 -> 39.451042 | L4: ='Simulasi Program'!$D$92 -> 150 | M4: ='Simulasi Program'!$E$92 -> 400 | N4: =J4*5% -> 882.05708 | O4: =J4*2% -> 352.82283 | P4: =200*H4 -> 268 | Q4: =(SUM($J$4:$P$4))*'Simulasi Program'!$E$104 -> 0 | R4: =(SUM($J$4:$P$4))*'Simulasi Program'!$E$105 -> 0 | S4: =(SUM($J$4:$P$4))*'Simulasi Program'!$E$106 -> 0 | T4: =(SUM($J$4:$P$4))*'Simulasi Program'!$E$107 -> 0 | U4: =(SUM($J$4:$P$4))*'Simulasi Program'!$E$108 -> 0 | V4: =(SUM($J$4:$P$4))*'Simulasi Program'!$E$109 -> 986.67362 | W4: =SUM(J4:V4) -> 20720.146 | X4: =W4*'Simulasi Program'!$E$111 -> 1036.0073 | Y4: =SUM(W4:X4) -> 21756.153 | Z4: =G4 -> 13165.031 | AA4: =K4/$H4 -> 29.441076 | AB4: =L4/$H4 -> 111.9403 | AC4: =M4/$H4 -> 298.50746 | AD4: =Z4*'Simulasi Program'!$E$100 -> 658.25155 | AE4: ='Simulasi Program'!$E$101*Z4 -> 263.30062 | AF4: =P4/$H4 -> 200 | AG4: =(SUM(Z4:AF4))*'Simulasi Program'!$E$104 -> 0 | AH4: =(SUM(Z4:AF4))*'Simulasi Program'!$E$105 -> 0 | AI4: =(SUM(Z4:AF4))*'Simulasi Program'!$E$106 -> 0 | AJ4: =(SUM(Z4:AF4))*'Simulasi Program'!$E$107 -> 0 | AK4: =(SUM(Z4:AF4))*'Simulasi Program'!$E$108 -> 0 | AL4: =(SUM(Z4:AF4))*'Simulasi Program'!$E$109 -> 736.3236 | AM4: =SUM(Z4:AL4) -> 15462.796 | AN4: =AM4*5% -> 773.13978 | AO4: =SUM(AM4:AN4) -> 16235.935 | AP4: 6 | AQ4: =AP4*Y4 -> 130536.92 | AR4: =AP4*H4*AO4 -> 130536.92
C5: ='Simulasi Program'!E38 -> GALVALUM MOTHER BORON 0.15-1219-AZ70-G550- | D5: ='Simulasi Program'!C38 -> Type 001.2 | E5: ='Simulasi Program'!I29 -> 0.725 | F5: ='Simulasi Program'!$D$23 -> 17863 | G5: ='Simulasi Program'!$J$28 -> 13165.031 | H5: ='Simulasi Program'!H12 -> 1.44 | I5: =G5*H5 -> 18957.645 | J5: =I5 -> 18957.645 | K5: ='Simulasi Program'!$C$87 -> 39.451042 | L5: ='Simulasi Program'!$D$92 -> 150 | M5: ='Simulasi Program'!$E$92 -> 400 | N5: =J5*5% -> 947.88223 | O5: =J5*2% -> 379.15289 | P5: =200*H5 -> 288 | Q5: =(SUM($J$5:$P$5))*'Simulasi Program'!$E$104 -> 0 | R5: =(SUM($J$5:$P$5))*'Simulasi Program'!$E$105 -> 0 | S5: =(SUM($J$5:$P$5))*'Simulasi Program'!$E$106 -> 0 | T5: =(SUM($J$5:$P$5))*'Simulasi Program'!$E$107 -> 0 | U5: =(SUM($J$5:$P$5))*'Simulasi Program'!$E$108 -> 0 | V5: =(SUM($J$5:$P$5))*'Simulasi Program'!$E$109 -> 1058.1065 | W5: =SUM(J5:V5) -> 22220.237 | X5: =W5*'Simulasi Program'!$E$111 -> 1111.0119 | Y5: =SUM(W5:X5) -> 23331.249 | Z5: =G5 -> 13165.031 | AA5: =K5/$H5 -> 27.396557 | AB5: =L5/$H5 -> 104.16667 | AC5: =M5/$H5 -> 277.77778 | AD5: =Z5*'Simulasi Program'!$E$100 -> 658.25155 | AE5: ='Simulasi Program'!$E$101*Z5 -> 263.30062 | AF5: =P5/$H5 -> 200 | AG5: =(SUM(Z5:AF5))*'Simulasi Program'!$E$104 -> 0 | AH5: =(SUM(Z5:AF5))*'Simulasi Program'!$E$105 -> 0 | AI5: =(SUM(Z5:AF5))*'Simulasi Program'!$E$106 -> 0 | AJ5: =(SUM(Z5:AF5))*'Simulasi Program'!$E$107 -> 0 | AK5: =(SUM(Z5:AF5))*'Simulasi Program'!$E$108 -> 0 | AL5: =(SUM(Z5:AF5))*'Simulasi Program'!$E$109 -> 734.79621 | AM5: =SUM(Z5:AL5) -> 15430.72 | AN5: =AM5*5% -> 771.53602 | AO5: =SUM(AM5:AN5) -> 16202.256 | AP5: 6 | AQ5: =AP5*Y5 -> 139987.5 | AR5: =AP5*H5*AO5 -> 139987.5
X9: Pricelist HFG saat ini : | Y9: 27400 | Z9: (Harga Dasar + Extra Margin)
